<?xml version="1.0" ?>
<!-- =================================================================================== -->
<!-- |    This document was autogenerated by xacro from r2000ic125l.xacro              | -->
<!-- |    EDITING THIS FILE BY HAND IS NOT RECOMMENDED                                 | -->
<!-- =================================================================================== -->
<robot name="fanuc_r2000ic125l">
  <!-- links: main serial chain -->
  <link name="base_link">
   <inertial> 
       <mass value="150.0"/> 
       <origin rpy="0 0 0" xyz="0 0 0"/> 
       <mass value="150.0"/> 
       <inertia ixx="1" ixy="0" ixz="0" iyy="1" iyz="0" izz="1"/>
    </inertial> 
    <visual>
      <origin rpy="0 0 0" xyz="0 0 0"/>
      <geometry>
        <mesh filename="package://fanuc_r2000ic_support/meshes/r2000ic125l/visual/base_link.stl"/>
      </geometry>
      <material name="">
        <color rgba="0.4 0.4 0.4 1.0"/>
      </material>
    </visual>
    <collision>
      <origin rpy="0 0 0" xyz="0 0 0"/>
      <geometry>
        <mesh filename="package://fanuc_r2000ic_support/meshes/r2000ic125l/collision/base_link.stl"/>
      </geometry>
    </collision>
  </link>
  <link name="link_1">
     <inertial> 
       <mass value="250"/> 
       <origin rpy="0 0 0" xyz="0 0 0"/> 
       <mass value="250"/> 
       <inertia ixx="1" ixy="0" ixz="0" iyy="1" iyz="0" izz="1"/> 
    </inertial> 
    <visual>
      <origin rpy="0 0 0" xyz="0 0 0"/>
      <geometry>
        <mesh filename="package://fanuc_r2000ic_support/meshes/r2000ic125l/visual/link_1.stl"/>
      </geometry>
      <material name="">
        <color rgba="0.96 0.76 0.13 1.0"/>
      </material>
    </visual>
    <collision>
      <origin rpy="0 0 0" xyz="0 0 0"/>
      <geometry>
        <mesh filename="package://fanuc_r2000ic_support/meshes/r2000ic125l/collision/link_1.stl"/>
      </geometry>
    </collision>
  </link>
  <link name="link_2">
    <inertial> 
       <mass value="200"/> 
       <origin rpy="0 0 0" xyz="0 0 0"/> 
       <mass value="200"/> 
       <inertia ixx="1" ixy="0" ixz="0" iyy="1" iyz="0" izz="1"/>
    </inertial> 
    <visual>
      <origin rpy="0 0 0" xyz="0 0 0"/>
      <geometry>
        <mesh filename="package://fanuc_r2000ic_support/meshes/r2000ic125l/visual/link_2.stl"/>
      </geometry>
      <material name="">
        <color rgba="0.96 0.76 0.13 1.0"/>
      </material>
    </visual>
    <collision>
      <origin rpy="0 0 0" xyz="0 0 0"/>
      <geometry>
        <mesh filename="package://fanuc_r2000ic_support/meshes/r2000ic125l/collision/link_2.stl"/>
      </geometry>
    </collision>
  </link>
  <link name="link_3">
    <inertial> 
       <mass value="150"/> 
       <origin rpy="0 0 0" xyz="0 0 0"/> 
       <mass value="150"/> 
       <inertia ixx="1" ixy="0" ixz="0" iyy="1" iyz="0" izz="1"/>
    </inertial> 

    <visual>
      <origin rpy="0 0 0" xyz="0 0 0"/>
      <geometry>
        <mesh filename="package://fanuc_r2000ic_support/meshes/r2000ic125l/visual/link_3.stl"/>
      </geometry>
      <material name="">
        <color rgba="0.96 0.76 0.13 1.0"/>
      </material>
    </visual>
    <collision>
      <origin rpy="0 0 0" xyz="0 0 0"/>
      <geometry>
        <mesh filename="package://fanuc_r2000ic_support/meshes/r2000ic125l/collision/link_3.stl"/>
      </geometry>
    </collision>
  </link>
  <link name="link_4">
    <inertial> 
       <mass value="100"/> 
       <origin rpy="0 0 0" xyz="0 0 0"/> 
       <mass value="100"/> 
       <inertia ixx="1" ixy="0" ixz="0" iyy="1" iyz="0" izz="1"/>
    </inertial> 

    <visual>
      <origin rpy="0 0 0" xyz="0.09 0 0"/>
      <geometry>
        <mesh filename="package://fanuc_r2000ic_support/meshes/r2000ic125l/visual/link_4.stl"/>
      </geometry>
      <material name="">
        <color rgba="0.96 0.76 0.13 1.0"/>
      </material>
    </visual>
    <collision>
      <origin rpy="0 0 0" xyz="0.09 0 0"/>
      <geometry>
        <mesh filename="package://fanuc_r2000ic_support/meshes/r2000ic125l/collision/link_4.stl"/>
      </geometry>
    </collision>
  </link>
  <link name="block">
    <inertial> 
       <mass value="50"/> 
       <origin rpy="0 0 0" xyz="0 0 0"/> 
       <mass value="50"/> 
       <inertia ixx="1" ixy="0" ixz="0" iyy="1" iyz="0" izz="1"/>
    </inertial> 

    <visual>
      <origin rpy="0 0 0" xyz="1.55 0 0.25"/>
      <geometry>
        <box size="0.1 1.85 0.3"/>
      </geometry>
      <material name="gray">
        <color rgba="0.5 0.5 0.5 1.0"/>
      </material>
    </visual>
    <collision>
      <origin rpy="0 0 0" xyz="1.55 0 0.25"/>
      <geometry>
        <box size="0.2 1.85 0.4"/>
      </geometry>
    </collision>
  </link>
  <link name="link_5">
    <inertial> 
       <mass value="50"/> 
       <origin rpy="0 0 0" xyz="0 0 0"/> 
       <mass value="50"/> 
       <inertia ixx="1" ixy="0" ixz="0" iyy="1" iyz="0" izz="1"/>
    </inertial> 

    <visual>
      <origin rpy="0 0 0" xyz="0.13 0 0"/>
      <geometry>
        <mesh filename="package://fanuc_r2000ic_support/meshes/r2000ic125l/visual/link_5.stl"/>
      </geometry>
      <material name="">
        <color rgba="0.96 0.76 0.13 1.0"/>
      </material>
    </visual>
    <collision>
      <origin rpy="0 0 0" xyz="0.13 0 0"/>
      <geometry>
        <mesh filename="package://fanuc_r2000ic_support/meshes/r2000ic125l/collision/link_5.stl"/>
      </geometry>
    </collision>
  </link>
  <link name="link_6">
    <inertial> 
       <mass value="25"/> 
       <origin rpy="0 0 0" xyz="0 0 0"/> 
       <mass value="25"/> 
       <inertia ixx="1" ixy="0" ixz="0" iyy="1" iyz="0" izz="1"/>
    </inertial> 

    <visual>
      <origin rpy="0 0 0" xyz="0.13 0 0"/>
      <geometry>
        <mesh filename="package://fanuc_r2000ic_support/meshes/r2000ic125l/visual/link_6.stl"/>
      </geometry>
      <material name="">
        <color rgba="0.15 0.15 0.15 1.0"/>
      </material>
    </visual>
    <collision>
      <origin rpy="0 0 0" xyz="0.13 0 0"/>
      <geometry>
        <mesh filename="package://fanuc_r2000ic_support/meshes/r2000ic125l/collision/link_6.stl"/>
      </geometry>
    </collision>
  </link>
  
  <!-- Block for fingers attachment -->
  <link name="gripper_base">
    <inertial> 
       <mass value="15"/> 
       <origin rpy="0 0 0" xyz="0 0 0"/> 
       <mass value="15"/> 
       <inertia ixx="1" ixy="0" ixz="0" iyy="1" iyz="0" izz="1"/>
    </inertial> 

    <visual>
      <origin rpy="0 0 0" xyz="0.17 0 0"/>
      <geometry>
        <box size="0.08 0.4 0.1"/>
      </geometry>
      <material name="gray">
        <color rgba="0.5 0.5 0.5 1.0"/>
      </material>
    </visual>
    <collision>
      <origin rpy="0 0 0" xyz="0.17 0 0"/>
      <geometry>
        <box size="0.08 0.4 0.1"/>
      </geometry>
    </collision>
  </link>
  
  <!-- Finger 1 -->
  <link name="finger_1">
    <inertial> 
       <mass value="10"/> 
       <origin rpy="0 0 0" xyz="0 0 0"/> 
       <mass value="10"/> 
       <inertia ixx="1" ixy="0" ixz="0" iyy="1" iyz="0" izz="1"/>
    </inertial> 

    <visual>
      <origin rpy="0 0 0" xyz="0.27 -0.22 0"/>
      <geometry>
        <box size="0.25 0.05 0.1"/>
      </geometry>
      <material name="gray">
        <color rgba="0.5 0.5 0.5 1.0"/>
      </material>
    </visual>
    <collision>
      <origin rpy="0 0 0" xyz="0.27 -0.22 0"/>
      <geometry>
        <box size="0.25 0.05 0.1"/>
      </geometry>
    </collision>
  </link>
  <!-- Finger 2 -->
  <link name="finger_2">
    <inertial> 
       <mass value="10"/> 
       <origin rpy="0 0 0" xyz="0 0 0"/> 
       <mass value="10"/> 
       <inertia ixx="1" ixy="0" ixz="0" iyy="1" iyz="0" izz="1"/>
    </inertial> 

    <visual>
      <origin rpy="0 0 0" xyz="0.27 0.22 0"/>
      <geometry>
        <box size="0.25 0.05 0.1"/>
      </geometry>
      <material name="gray">
        <color rgba="0.5 0.5 0.5 1.0"/>
      </material>
    </visual>
    <collision>
      <origin rpy="0 0 0" xyz="0.27 0.22 0"/>
      <geometry>
        <box size="0.25 0.05 0.1"/>
      </geometry>
    </collision>
  </link>
  
  
  <!-- joints: main serial chain -->
  <joint name="joint_1" type="revolute">
    <origin rpy="0 0 0" xyz="0 0 .670"/>
    <parent link="base_link"/>
    <child link="link_1"/>
    <axis xyz="0 0 1"/>
    <limit effort="0" lower="-3.2288591161895095" upper="3.2288591161895095" velocity="2.2689280275926285"/>
  </joint>
  <joint name="joint_2" type="revolute">
    <origin rpy="0 0 0" xyz="0.312 0 0"/>
    <parent link="link_1"/>
    <child link="link_2"/>
    <axis xyz="0 1 0"/>
    <limit effort="0" lower="-1.0471975511965976" upper="0.4363323129985824" velocity="2.007128639793479"/>
  </joint>
  <joint name="joint_3" type="revolute">
    <origin rpy="0 0 0" xyz="0 0 1.075"/>
    <parent link="link_2"/>
    <child link="link_3"/>
    <axis xyz="0 -1 0"/>
    <limit effort="0" lower="-1.3089969389957472" upper="3.141592653589793" velocity="2.181661564992912"/>
  </joint>
  <joint name="joint_4" type="prismatic">
    <origin rpy="0 0 0" xyz="0 0 0.225"/>
    <parent link="link_3"/>
    <child link="link_4"/>
    <axis xyz="0 1 0"/>
    <limit effort="0" lower="-0.7853981633974483" upper="0.7853981633974483" velocity="3.141592653589793"/>
  </joint>
  <joint name="joint_block" type="fixed">
    <origin rpy="0 0 0" xyz="0 0 0"/>
    <parent link="link_3"/>
    <child link="block"/>
  </joint>
  <joint name="joint_5" type="revolute">
    <origin rpy="0 0 0" xyz="1.730 0 0"/>
    <parent link="link_4"/>
    <child link="link_5"/>
    <axis xyz="0 -1 0"/>
    <limit effort="0" lower="-1.0471975511965976" upper="1.0471975511965976" velocity="3.141592653589793"/>
  </joint>
  <joint name="joint_6" type="revolute">
    <origin rpy="0 0 0" xyz="0.215 0 0"/>
    <parent link="link_5"/>
    <child link="link_6"/>
    <axis xyz="-1 0 0"/>
    <limit effort="0" lower="-6.283185307179586" upper="6.283185307179586" velocity="4.537856055185257"/>
  </joint>
  <joint name="joint_gripper_base" type="fixed">
    <origin rpy="0 0 0" xyz="0 0 0"/>
    <parent link="link_6"/>
    <child link="gripper_base"/>
  </joint>
  <joint name="gripper_base-finger_1" type="prismatic">
    <origin rpy="0 0 0" xyz="0 0.05 0"/>
    <parent link="gripper_base"/>
    <child link="finger_1"/>
    <axis xyz="0 1 0"/>
    <limit effort="1.0" lower="0" upper="0.14" velocity="0.1"/>
  </joint>
  <joint name="gripper_base-finger_2" type="prismatic">
    <origin rpy="0 0 0" xyz="0 -0.05 0"/>
    <parent link="gripper_base"/>
    <child link="finger_2"/>
    <axis xyz="0 1 0"/>
    <limit effort="1.0" lower="0" upper="-0.14" velocity="0.1"/>
  </joint>
  <!-- ROS-Industrial 'base' frame: base_link to Fanuc World Coordinates transform -->
  <link name="base"/>
  <joint name="base_link-base" type="fixed">
    <origin rpy="0 0 0" xyz="0 0 0.670"/>
    <parent link="base_link"/>
    <child link="base"/>
  </joint>
  <!-- ROS-Industrial 'flange' frame: attachment point for EEF models -->
  <link name="flange"/>
  <joint name="joint_6-flange" type="fixed">
    <origin rpy="0 0 0" xyz="0 0 0"/>
    <parent link="link_6"/>
    <child link="flange"/>
  </joint>
  <!-- ROS-Industrial 'tool0' frame: all-zeros tool frame -->
  <link name="tool0"/>
  <joint name="link_6-tool0" type="fixed">
    <origin rpy=" 0 0 0" xyz="0.2 0 0"/>
    <parent link="link_6"/>
    <child link="tool0"/>
  </joint>
</robot>

